<mujoco model="avada4">
  <compiler angle="radian" meshdir="meshes/" autolimits="true"/>
  <statistic meansize="0.144785" extent="1.23314" center="0.025392 2.0634e-05 -0.245975"/>
  <default>
    <joint damping="0.001" armature="0.01" frictionloss="0.1"/>
  </default>

  <asset>
    <mesh name="pelvis" file="pelvis.STL"/>
    <mesh name="waist_roll_link" file="waist_roll_link.STL"/>
    <mesh name="waist_yaw_link" file="waist_yaw_link.STL"/>
    <mesh name="waist_pitch_link" file="waist_pitch_link.STL"/>
    <mesh name="left_shoulder_pitch_link" file="left_shoulder_pitch_link.STL"/>
    <mesh name="left_shoulder_roll_link" file="left_shoulder_roll_link.STL"/>
    <mesh name="left_shoulder_yaw_link" file="left_shoulder_yaw_link.STL"/>
    <mesh name="left_elbow_link" file="left_elbow_link.STL"/>
    <mesh name="left_wrist_yaw_link" file="left_wrist_yaw_link.STL"/>
    <mesh name="left_wrist_pitch_link" file="left_wrist_pitch_link.STL"/>
    <mesh name="left_wrist_roll_link" file="left_wrist_roll_link.STL"/>
    <mesh name="right_shoulder_pitch_link" file="right_shoulder_pitch_link.STL"/>
    <mesh name="right_shoulder_roll_link" file="right_shoulder_roll_link.STL"/>
    <mesh name="right_shoulder_yaw_link" file="right_shoulder_yaw_link.STL"/>
    <mesh name="right_elbow_link" file="right_elbow_link.STL"/>
    <mesh name="right_wrist_yaw_link" file="right_wrist_yaw_link.STL"/>
    <mesh name="right_wrist_pitch_link" file="right_wrist_pitch_link.STL"/>
    <mesh name="right_wrist_roll_link" file="right_wrist_roll_link.STL"/>
    <mesh name="left_hip_roll_link" file="left_hip_roll_link.STL"/>
    <mesh name="left_hip_yaw_link" file="left_hip_yaw_link.STL"/>
    <mesh name="left_hip_pitch_link" file="left_hip_pitch_link.STL"/>
    <mesh name="left_knee_link" file="left_knee_link.STL"/>
    <mesh name="left_ankle_pitch_link" file="left_ankle_pitch_link.STL"/>
    <mesh name="left_ankle_roll_link" file="left_ankle_roll_link.STL"/>
    <mesh name="right_hip_roll_link" file="right_hip_roll_link.STL"/>
    <mesh name="right_hip_yaw_link" file="right_hip_yaw_link.STL"/>
    <mesh name="right_hip_pitch_link" file="right_hip_pitch_link.STL"/>
    <mesh name="right_knee_link" file="right_knee_link.STL"/>
    <mesh name="right_ankle_pitch_link" file="right_ankle_pitch_link.STL"/>
    <mesh name="right_ankle_roll_link" file="right_ankle_roll_link.STL"/>
  </asset>

  <worldbody>
    <body name="pelvis" pos="0 0 0.9" > 
      <inertial pos="0.04524 -0.0028201 -0.023931" mass="6.5796" fullinertia="0.057709 0.010445 0.056495 -4.25E-06 -7.807E-05 -3.427E-05"/>
      <!-- 有joint了就会往下掉了 -->
      <freejoint name="pelvis"/>
      <geom type="mesh" contype="0" conaffinity="0" group="1" density="0" rgba="0.89804 0.91765 0.92941 1" mesh="pelvis"/>
      <geom type="mesh" rgba="0.89804 0.91765 0.92941 1" mesh="pelvis"/>
      <body name="waist_roll_link">
        <inertial pos="0.13611 -0.0026969 0.010109" quat="0.506161 0.506161 -0.493762 0.493762" mass="0.77779" diaginertia="0.00062195 0.00060541 0.0005688"/>
        <joint name="waist_roll_joint" pos="0 0 0" axis="1 0 0" range="-0.5236 0.5236" actuatorfrcrange="-400 400"/>
        <geom type="mesh" contype="0" conaffinity="0" group="1" density="0" rgba="0.89804 0.91765 0.92941 1" mesh="waist_roll_link"/>
        <geom type="mesh" rgba="0.89804 0.91765 0.92941 1" mesh="waist_roll_link"/>
        <body name="waist_yaw_link" pos="0.136 -0.00269696 0.005">
          <inertial pos="-7.5182e-08 -5.6001e-08 0.022793" quat="0.707107 0 0 0.707107" mass="0.67921" diaginertia="0.0010484 0.0010239 0.00036408"/>
          <joint name="waist_yaw_joint" pos="0 0 0" axis="0 0 1" range="-0.5236 0.5236" actuatorfrcrange="-400 400"/>
          <geom type="mesh" contype="0" conaffinity="0" group="1" density="0" rgba="0.89804 0.91765 0.92941 1" mesh="waist_yaw_link"/>
          <geom type="mesh" rgba="0.89804 0.91765 0.92941 1" mesh="waist_yaw_link"/>
          <body name="waist_pitch_link" pos="0 0 0.1">
            <inertial pos="0.0051469 -1.2872e-08 0.19417" quat="0.999542 0 -0.0302618 0" mass="19.42" diaginertia="0.476932 0.458 0.197658"/>
            <joint name="waist_pitch_joint" pos="0 0 0" axis="0 1 0" range="-0.5236 1.0472" actuatorfrcrange="-400 400"/>
            <geom type="mesh" contype="0" conaffinity="0" group="1" density="0" rgba="0.89804 0.91765 0.92941 1" mesh="waist_pitch_link"/>
            <geom type="mesh" rgba="0.89804 0.91765 0.92941 1" mesh="waist_pitch_link"/>
            <body name="left_shoulder_pitch_link" pos="-0.02 0.1764 0.3302">
              <inertial pos="-0.00044872 0.052703 2.4298e-07" quat="0.00832478 0.706905 -0.00833574 0.70721" mass="0.80756" diaginertia="0.00071049 0.00067615 0.00064091"/>
              <joint name="left_shoulder_pitch_joint" pos="0 0 0" axis="0 1 0" range="-3.1416 0.7854" actuatorfrcrange="-400 400"/>
              <geom type="mesh" contype="0" conaffinity="0" group="1" density="0" rgba="0.89804 0.91765 0.92941 1" mesh="left_shoulder_pitch_link"/>
              <geom type="mesh" rgba="0.89804 0.91765 0.92941 1" mesh="left_shoulder_pitch_link"/>
              <body name="left_shoulder_roll_link" pos="0.037 0.055 0">
                <inertial pos="-0.029786 -1.5469e-05 -0.082382" quat="0.977616 0.0211632 0.182671 0.102232" mass="1.0192" diaginertia="0.0013631 0.00136041 0.000858351"/>
                <joint name="left_shoulder_roll_joint" pos="0 0 0" axis="1 0 0" range="-0.6981 3.1416" actuatorfrcrange="-400 400"/>
                <geom type="mesh" contype="0" conaffinity="0" group="1" density="0" rgba="0.89804 0.91765 0.92941 1" mesh="left_shoulder_roll_link"/>
                <geom type="mesh" rgba="0.89804 0.91765 0.92941 1" mesh="left_shoulder_roll_link"/>
                <body name="left_shoulder_yaw_link" pos="-0.035 0 -0.125">
                  <inertial pos="1.2055e-08 0.00039438 -0.10267" quat="0.999993 0.0037643 -5.41561e-07 0.000143867" mass="0.91899" diaginertia="0.0014881 0.00141859 0.000824836"/>
                  <joint name="left_shoulder_yaw_joint" pos="0 0 0" axis="0 0 1" range="-1.5708 1.5708" actuatorfrcrange="-400 400"/>
                  <geom type="mesh" contype="0" conaffinity="0" group="1" density="0" rgba="0.89804 0.91765 0.92941 1" mesh="left_shoulder_yaw_link"/>
                  <geom type="mesh" rgba="0.89804 0.91765 0.92941 1" mesh="left_shoulder_yaw_link"/>
                  <body name="left_elbow_link" pos="0 -0.037 -0.115">
                    <inertial pos="0 0.027765 -0.081713" quat="0.695449 0.127869 -0.127869 0.695449" mass="1.1024" diaginertia="0.00155458 0.0015351 0.000973818"/>
                    <joint name="left_elbow_joint" pos="0 0 0" axis="0 1 0" range="-2.4435 0.1745" limited="true" actuatorfrcrange="-400 400"/>
                    <geom type="mesh" contype="0" conaffinity="0" group="1" density="0" rgba="0.89804 0.91765 0.92941 1" mesh="left_elbow_link"/>
                    <geom type="mesh" rgba="0.89804 0.91765 0.92941 1" mesh="left_elbow_link"/>
                    <body name="left_wrist_yaw_link" pos="0 0.035 -0.125" quat="0.707107 0 0.707107 0">
                      <inertial pos="0.053864 0.00012644 0.0015228" quat="0.0383592 0.704709 0.0374418 0.707468" mass="0.67025" diaginertia="0.00101043 0.000992222 0.00044227"/>
                      <joint name="left_wrist_yaw_joint" pos="0 0 0" axis="1 0 0" range="-1.5708 1.5708" actuatorfrcrange="-400 400"/>
                      <geom type="mesh" contype="0" conaffinity="0" group="1" density="0" rgba="0.89804 0.91765 0.92941 1" mesh="left_wrist_yaw_link"/>
                      <geom type="mesh" rgba="0.89804 0.91765 0.92941 1" mesh="left_wrist_yaw_link"/>
                      <body name="left_wrist_pitch_link" pos="0.143 0.0019361 0.0173926" quat="0.998364 -0.0553968 0.0141131 -0.000783099">
                        <inertial pos="0.0022975 -6.2346e-09 3.4863e-09" quat="0.5 0.5 -0.5 0.5" mass="0.0012195" diaginertia="3e-08 2e-08 2e-08"/>
                        <joint name="left_wrist_pitch_joint" pos="0 0 0" axis="0 1 0" range="-1.3963 1.3963" actuatorfrcrange="-400 400"/>
                        <geom type="mesh" contype="0" conaffinity="0" group="1" density="0" rgba="0.89804 0.91765 0.92941 1" mesh="left_wrist_pitch_link"/>
                        <geom type="mesh" rgba="0.89804 0.91765 0.92941 1" mesh="left_wrist_pitch_link"/>
                        <body name="left_wrist_roll_link" pos="0.0085 0 0">
                          <inertial pos="0.082689 0.0062323 0.0064285" quat="0.0726249 0.743879 -0.0231708 0.663952" mass="0.45656" diaginertia="0.00125175 0.000965711 0.000404781"/>
                          <joint name="left_wrist_roll_joint" pos="0 0 0" axis="0 0 1" range="-0.5236 0.6981" actuatorfrcrange="-400 400"/>
                          <geom type="mesh" contype="0" conaffinity="0" group="1" density="0" rgba="0.89804 0.91765 0.92941 1" mesh="left_wrist_roll_link"/>
                          <geom type="mesh" rgba="0.89804 0.91765 0.92941 1" mesh="left_wrist_roll_link"/>
                        </body>
                      </body>
                    </body>
                  </body>
                </body>
              </body>
            </body>
            <body name="right_shoulder_pitch_link" pos="-0.02 -0.1764 0.3302">
              <inertial pos="0.00044872 -0.052703 2.4354e-07" quat="0.00833574 0.70721 -0.00832478 0.706905" mass="0.80756" diaginertia="0.00071049 0.00067615 0.00064091"/>
              <joint name="right_shoulder_pitch_joint" pos="0 0 0" axis="0 1 0" range="-3.1416 0.7854" actuatorfrcrange="-400 400"/>
              <geom type="mesh" contype="0" conaffinity="0" group="1" density="0" rgba="0.89804 0.91765 0.92941 1" mesh="right_shoulder_pitch_link"/>
              <geom type="mesh" rgba="0.89804 0.91765 0.92941 1" mesh="right_shoulder_pitch_link"/>
              <body name="right_shoulder_roll_link" pos="-0.037 -0.055 0">
                <inertial pos="0.029786 1.5469e-05 -0.082382" quat="0.977616 -0.0211632 -0.182671 0.102232" mass="1.0192" diaginertia="0.0013631 0.00136041 0.000858351"/>
                <joint name="right_shoulder_roll_joint" pos="0 0 0" axis="1 0 0" range="-3.1416 0.6981" actuatorfrcrange="-400 400"/>
                <geom type="mesh" contype="0" conaffinity="0" group="1" density="0" rgba="0.89804 0.91765 0.92941 1" mesh="right_shoulder_roll_link"/>
                <geom type="mesh" rgba="0.89804 0.91765 0.92941 1" mesh="right_shoulder_roll_link"/>
                <body name="right_shoulder_yaw_link" pos="0.035 0 -0.125">
                  <inertial pos="-3.3047e-08 -0.00039438 -0.10267" quat="0.999993 -0.0037643 5.41561e-07 0.000143867" mass="0.91899" diaginertia="0.0014881 0.00141859 0.000824836"/>
                  <joint name="right_shoulder_yaw_joint" pos="0 0 0" axis="0 0 1" range="-1.5708 1.5708" actuatorfrcrange="-400 400"/>
                  <geom type="mesh" contype="0" conaffinity="0" group="1" density="0" rgba="0.89804 0.91765 0.92941 1" mesh="right_shoulder_yaw_link"/>
                  <geom type="mesh" rgba="0.89804 0.91765 0.92941 1" mesh="right_shoulder_yaw_link"/>
                  <body name="right_elbow_link" pos="0 0.037 -0.115">
                    <inertial pos="0 -0.027765 -0.081713" quat="0.69545 -0.127867 0.127867 0.69545" mass="1.1024" diaginertia="0.00155462 0.00153506 0.000973849"/>
                    <joint name="right_elbow_joint" pos="0 0 0" axis="0 1 0" range="-2.4435 0.1745" actuatorfrcrange="-400 400"/>
                    <geom type="mesh" contype="0" conaffinity="0" group="1" density="0" rgba="0.89804 0.91765 0.92941 1" mesh="right_elbow_link"/>
                    <geom type="mesh" rgba="0.89804 0.91765 0.92941 1" mesh="right_elbow_link"/>
                    <body name="right_wrist_yaw_link" pos="0 -0.035 -0.125" quat="0.707107 0 0.707107 0">
                      <inertial pos="0.053864 -0.00012644 -0.0015228" quat="0.0374418 0.707468 0.0383592 0.704709" mass="0.67025" diaginertia="0.00101043 0.000992222 0.00044227"/>
                      <joint name="right_wrist_yaw_joint" pos="0 0 0" axis="1 0 0" range="-1.5708 1.5708" actuatorfrcrange="-400 400"/>
                      <geom type="mesh" contype="0" conaffinity="0" group="1" density="0" rgba="0.89804 0.91765 0.92941 1" mesh="right_wrist_yaw_link"/>
                      <geom type="mesh" rgba="0.89804 0.91765 0.92941 1" mesh="right_wrist_yaw_link"/>
                      <body name="right_wrist_pitch_link" pos="0.143 -0.0019361 -0.0173926" quat="0.998364 -0.0553968 -0.0141131 0.000783099">
                        <inertial pos="0.0022975 6.2346e-09 -3.4863e-09" quat="0.5 0.5 -0.5 0.5" mass="0.0012195" diaginertia="3e-08 2e-08 2e-08"/>
                        <joint name="right_wrist_pitch_joint" pos="0 0 0" axis="0 1 0" range="-1.3963 1.3963" actuatorfrcrange="-400 400"/>
                        <geom type="mesh" contype="0" conaffinity="0" group="1" density="0" rgba="0.89804 0.91765 0.92941 1" mesh="right_wrist_pitch_link"/>
                        <geom type="mesh" rgba="0.89804 0.91765 0.92941 1" mesh="right_wrist_pitch_link"/>
                        <body name="right_wrist_roll_link" pos="0.0085 0 0" quat="0.9999 0 0.0141348 0">
                          <inertial pos="0.082502 -0.0062021 0.0077858" quat="-0.0781284 0.753248 0.01378 0.652935" mass="0.45656" diaginertia="0.00125254 0.000964496 0.000405195"/>
                          <joint name="right_wrist_roll_joint" pos="0 0 0" axis="-0.0282667 0 0.9996" range="-0.6981 0.5236" actuatorfrcrange="-400 400"/>
                          <geom type="mesh" contype="0" conaffinity="0" group="1" density="0" rgba="0.89804 0.91765 0.92941 1" mesh="right_wrist_roll_link"/>
                          <geom type="mesh" rgba="0.89804 0.91765 0.92941 1" mesh="right_wrist_roll_link"/>
                        </body>
                      </body>
                    </body>
                  </body>
                </body>
              </body>
            </body>
          </body>
        </body>
      </body>
      <body name="left_hip_roll_link" pos="0.096 0.102303 -0.035">
        <inertial pos="0.047601 1.4826e-08 -0.0016085" quat="0 0.721182 0 0.692746" mass="0.82351" diaginertia="0.000744458 0.00068288 0.000665302"/>
        <joint name="left_hip_roll_joint" pos="0 0 0" axis="1 0 0" range="-0.7854 0.5236" actuatorfrcrange="-400 400"/>
        <geom type="mesh" contype="0" conaffinity="0" group="1" density="0" rgba="0.89804 0.91765 0.92941 1" mesh="left_hip_roll_link"/>
        <geom type="mesh" rgba="0.89804 0.91765 0.92941 1" mesh="left_hip_roll_link"/>
        <body name="left_hip_yaw_link" pos="0.05 0 -0.035">
          <inertial pos="5.8269e-09 3.9215e-09 -0.02534" quat="0.500002 0.499995 0.500001 0.500001" mass="0.39644" diaginertia="0.00020217 0.00019795 0.00018725"/>
          <joint name="left_hip_yaw_joint" pos="0 0 0" axis="0 0 1" range="-0.8727 0.8727" actuatorfrcrange="-400 400"/>
          <geom type="mesh" contype="0" conaffinity="0" group="1" density="0" rgba="0.89804 0.91765 0.92941 1" mesh="left_hip_yaw_link"/>
          <geom type="mesh" rgba="0.89804 0.91765 0.92941 1" mesh="left_hip_yaw_link"/>
          <body name="left_hip_pitch_link" pos="0 -0.001 -0.044">
            <inertial pos="-0.026282 -2.0455e-05 -0.17181" quat="0.999552 1.57847e-05 -0.029901 0.000928217" mass="6.4776" diaginertia="0.0556794 0.055297 0.0191946"/>
            <joint name="left_hip_pitch_joint" pos="0 0 0" axis="0 1 0" range="-2.5307 0.6981" actuatorfrcrange="-400 400"/>
            <geom type="mesh" contype="0" conaffinity="0" group="1" density="0" rgba="0.89804 0.91765 0.92941 1" mesh="left_hip_pitch_link"/>
            <geom type="mesh" rgba="0.89804 0.91765 0.92941 1" mesh="left_hip_pitch_link"/>
            <body name="left_knee_link" pos="-0.03 0 -0.324">
              <inertial pos="0.019387 0.0016128 -0.15668" quat="0.999172 -0.0048333 -0.0133671 -0.0381107" mass="1.3874" diaginertia="0.0129099 0.0122063 0.00185586"/>
              <joint name="left_knee_joint" pos="0 0 0" axis="0 1 0" range="0 2.5307" actuatorfrcrange="-400 400"/>
              <geom type="mesh" contype="0" conaffinity="0" group="1" density="0" rgba="0.89804 0.91765 0.92941 1" mesh="left_knee_link"/>
              <geom type="mesh" rgba="0.89804 0.91765 0.92941 1" mesh="left_knee_link"/>
              <body name="left_ankle_pitch_link" pos="0.0375 0 -0.326" quat="0.999914 0 0.0131263 0">
                <inertial pos="3.0174e-09 -6.2e-09 -0.0022975" mass="0.0012195" diaginertia="3e-08 2e-08 2e-08"/>
                <joint name="left_ankle_pitch_joint" pos="0 0 0" axis="0 1 0" range="-0.5236 0.7854" actuatorfrcrange="-400 400"/>
                <geom type="mesh" contype="0" conaffinity="0" group="1" density="0" rgba="0.89804 0.91765 0.92941 1" mesh="left_ankle_pitch_link"/>
                <geom type="mesh" rgba="0.89804 0.91765 0.92941 1" mesh="left_ankle_pitch_link"/>
                <body name="left_ankle_roll_link" pos="0 0 -0.0085" quat="1 -0.000354333 0 0">
                  <inertial pos="0.038053 0 -0.04952" quat="0 0.706325 0 0.707888" mass="0.55286" diaginertia="0.00308251 0.0028003 0.000925029"/>
                  <joint name="left_ankle_roll_joint" pos="0 0 0" axis="1 0 0" range="-0.6109 0.5236" actuatorfrcrange="-400 400"/>
                  <geom type="mesh" contype="0" conaffinity="0" group="1" density="0" rgba="0.89804 0.91765 0.92941 1" mesh="left_ankle_roll_link"/>
                  <geom type="mesh" rgba="0.89804 0.91765 0.92941 1" mesh="left_ankle_roll_link"/>
                </body>
              </body>
            </body>
          </body>
        </body>
      </body>
      <body name="right_hip_roll_link" pos="0.096 -0.107697 -0.035">
        <inertial pos="0.047601 1.4826e-08 -0.0016085" quat="0 0.721182 0 0.692746" mass="0.82351" diaginertia="0.000744458 0.00068288 0.000665302"/>
        <joint name="right_hip_roll_joint" pos="0 0 0" axis="1 0 0" range="-0.5236 0.7854" actuatorfrcrange="-400 400"/>
        <geom type="mesh" contype="0" conaffinity="0" group="1" density="0" rgba="0.89804 0.91765 0.92941 1" mesh="right_hip_roll_link"/>
        <geom type="mesh" rgba="0.89804 0.91765 0.92941 1" mesh="right_hip_roll_link"/>
        <body name="right_hip_yaw_link" pos="0.05 0 -0.035">
          <inertial pos="5.8269e-09 3.9215e-09 -0.02534" quat="0.500002 0.499995 0.500001 0.500001" mass="0.39644" diaginertia="0.00020217 0.00019795 0.00018725"/>
          <joint name="right_hip_yaw_joint" pos="0 0 0" axis="0 0 1" range="-0.8727 0.8727" actuatorfrcrange="-400 400"/>
          <geom type="mesh" contype="0" conaffinity="0" group="1" density="0" rgba="0.89804 0.91765 0.92941 1" mesh="right_hip_yaw_link"/>
          <geom type="mesh" rgba="0.89804 0.91765 0.92941 1" mesh="right_hip_yaw_link"/>
          <body name="right_hip_pitch_link" pos="0 0.001 -0.044">
            <inertial pos="-0.026282 -2.0455e-05 -0.17181" quat="0.999552 1.57847e-05 -0.029901 0.000928217" mass="6.4776" diaginertia="0.0556794 0.055297 0.0191946"/>
            <joint name="right_hip_pitch_joint" pos="0 0 0" axis="0 1 0" range="-2.5307 0.6981" actuatorfrcrange="-400 400"/>
            <geom type="mesh" contype="0" conaffinity="0" group="1" density="0" rgba="0.89804 0.91765 0.92941 1" mesh="right_hip_pitch_link"/>
            <geom type="mesh" rgba="0.89804 0.91765 0.92941 1" mesh="right_hip_pitch_link"/>
            <body name="right_knee_link" pos="-0.03 0 -0.324">
              <inertial pos="0.019387 0.0016128 -0.15668" quat="0.999172 -0.0048333 -0.0133671 -0.0381107" mass="1.3874" diaginertia="0.0129099 0.0122063 0.00185586"/>
              <joint name="right_knee_joint" pos="0 0 0" axis="0 1 0" range="0 2.4407" actuatorfrcrange="-400 400"/>
              <geom type="mesh" contype="0" conaffinity="0" group="1" density="0" rgba="0.89804 0.91765 0.92941 1" mesh="right_knee_link"/>
              <geom type="mesh" rgba="0.89804 0.91765 0.92941 1" mesh="right_knee_link"/>
              <body name="right_ankle_pitch_link" pos="0.0375 0 -0.326" quat="0.999914 0 0.0131263 0">
                <inertial pos="3.0174e-09 -6.2001e-09 -0.0022975" mass="0.0012195" diaginertia="3e-08 2e-08 2e-08"/>
                <joint name="right_ankle_pitch_joint" pos="0 0 0" axis="0 1 0" range="-0.5236 0.7854" actuatorfrcrange="-400 400"/>
                <geom type="mesh" contype="0" conaffinity="0" group="1" density="0" rgba="0.89804 0.91765 0.92941 1" mesh="right_ankle_pitch_link"/>
                <geom type="mesh" rgba="0.89804 0.91765 0.92941 1" mesh="right_ankle_pitch_link"/>
                <body name="right_ankle_roll_link" pos="0 0 -0.0085" quat="1 -0.000354333 0 0">
                  <inertial pos="0.038053 0 -0.04952" quat="0 0.707888 0 0.706325" mass="0.55286" diaginertia="0.00308251 0.0028003 0.000925029"/>
                  <joint name="right_ankle_roll_joint" pos="0 0 0" axis="1 0 0" range="-0.5236 0.6109" actuatorfrcrange="-400 400"/>
                  <geom type="mesh" contype="0" conaffinity="0" group="1" density="0" rgba="0.89804 0.91765 0.92941 1" mesh="right_ankle_roll_link"/>
                  <geom type="mesh" rgba="0.89804 0.91765 0.92941 1" mesh="right_ankle_roll_link"/>
                </body>
              </body>
            </body>
          </body>
        </body>
      </body>
    </body>
  </worldbody>

  <actuator>
    <motor name="left_hip_pitch_joint" joint="left_hip_pitch_joint"/>
    <motor name="left_hip_roll_joint" joint="left_hip_roll_joint"/>
    <motor name="left_hip_yaw_joint" joint="left_hip_yaw_joint"/>
    <motor name="left_knee_joint" joint="left_knee_joint"/>
    <motor name="left_ankle_pitch_joint" joint="left_ankle_pitch_joint"/>
    <motor name="left_ankle_roll_joint" joint="left_ankle_roll_joint"/>
    <motor name="right_hip_pitch_joint" joint="right_hip_pitch_joint"/>
    <motor name="right_hip_roll_joint" joint="right_hip_roll_joint"/>
    <motor name="right_hip_yaw_joint" joint="right_hip_yaw_joint"/>
    <motor name="right_knee_joint" joint="right_knee_joint"/>
    <motor name="right_ankle_pitch_joint" joint="right_ankle_pitch_joint"/>
    <motor name="right_ankle_roll_joint" joint="right_ankle_roll_joint"/>
    <motor name="waist_yaw_joint" joint="waist_yaw_joint"/>
    <motor name="waist_roll_joint" joint="waist_roll_joint"/>
    <motor name="waist_pitch_joint" joint="waist_pitch_joint"/>
    <motor name="left_shoulder_pitch_joint" joint="left_shoulder_pitch_joint"/>
    <motor name="left_shoulder_roll_joint" joint="left_shoulder_roll_joint"/>
    <motor name="left_shoulder_yaw_joint" joint="left_shoulder_yaw_joint"/>
    <motor name="left_elbow_joint" joint="left_elbow_joint"/>
    <motor name="left_wrist_roll_joint" joint="left_wrist_roll_joint"/>
    <motor name="left_wrist_pitch_joint" joint="left_wrist_pitch_joint"/>
    <motor name="left_wrist_yaw_joint" joint="left_wrist_yaw_joint"/>
    <motor name="right_shoulder_pitch_joint" joint="right_shoulder_pitch_joint"/>
    <motor name="right_shoulder_roll_joint" joint="right_shoulder_roll_joint"/>
    <motor name="right_shoulder_yaw_joint" joint="right_shoulder_yaw_joint"/>
    <motor name="right_elbow_joint" joint="right_elbow_joint"/>
    <motor name="right_wrist_roll_joint" joint="right_wrist_roll_joint"/>
    <motor name="right_wrist_pitch_joint" joint="right_wrist_pitch_joint"/>
    <motor name="right_wrist_yaw_joint" joint="right_wrist_yaw_joint"/>
  </actuator>

  <sensor>
    <!-- Actuator Force/Torque Sensors - measure the actual force/torque applied by the actuators -->
    <!-- <actuatorfrc name="left_hip_roll_actuator_force" actuator="left_hip_roll_joint"/>
    <actuatorfrc name="left_hip_yaw_actuator_force" actuator="left_hip_yaw_joint"/>
    <actuatorfrc name="left_hip_pitch_actuator_force" actuator="left_hip_pitch_joint"/>
    <actuatorfrc name="left_knee_actuator_force" actuator="left_knee_joint"/>
    <actuatorfrc name="left_ankle_pitch_actuator_force" actuator="left_ankle_pitch_joint"/>
    <actuatorfrc name="left_ankle_roll_actuator_force" actuator="left_ankle_roll_joint"/>

    <actuatorfrc name="right_hip_roll_actuator_force" actuator="right_hip_roll_joint"/>
    <actuatorfrc name="right_hip_yaw_actuator_force" actuator="right_hip_yaw_joint"/>
    <actuatorfrc name="right_hip_pitch_actuator_force" actuator="right_hip_pitch_joint"/>
    <actuatorfrc name="right_knee_actuator_force" actuator="right_knee_joint"/>
    <actuatorfrc name="right_ankle_pitch_actuator_force" actuator="right_ankle_pitch_joint"/>
    <actuatorfrc name="right_ankle_roll_actuator_force" actuator="right_ankle_roll_joint"/> -->
    <framepos name="pelvis_pos" objtype="body" objname="pelvis"/>
  </sensor>

  <statistic center="1.0 0.7 1.0" extent="0.8"/>
  <visual>
    <headlight diffuse="0.6 0.6 0.6" ambient="0.1 0.1 0.1" specular="0.9 0.9 0.9"/>
    <rgba haze="0.15 0.25 0.35 1"/>
    <global azimuth="-140" elevation="-20"/>
  </visual>
  <asset>
    <texture type="skybox" builtin="flat" rgb1="0 0 0" rgb2="0 0 0" width="512" height="3072"/>
    <texture type="2d" name="groundplane" builtin="checker" mark="edge" rgb1="0.2 0.3 0.4" rgb2="0.1 0.2 0.3" markrgb="0.8 0.8 0.8" width="300" height="300"/>
    <material name="groundplane" texture="groundplane" texuniform="true" texrepeat="5 5" reflectance="0.2"/>
  </asset>
  <worldbody>
    <light pos="1 0 3.5" dir="0 0 -1" directional="true"/>
    <geom name="floor" size="0 0 0.05" type="plane" material="groundplane"/>
  </worldbody>
</mujoco>
