<?xml version="1.0" encoding="utf-8"?>
<!-- This URDF was automatically created by SolidWorks to URDF Exporter! Originally created by Stephen Brawner (brawner@gmail.com) 
     Commit Version: 1.6.0-4-g7f85cfe  Build Version: 1.6.7995.38578
     For more information, please see http://wiki.ros.org/sw_urdf_exporter -->
<robot
  name="avada4">
  <mujoco>
    <compiler 
      meshdir="../meshes" 
      balanceinertia="true"
      discardvisual="false"/>
  </mujoco>

  <link
    name="pelvis">
    <inertial>
      <origin
        xyz="0.04524 -0.0028201 -0.023931"
        rpy="0 0 0" />
      <mass
        value="6.5796" />
      <inertia
        ixx="0.057709"
        ixy="-4.25E-06"
        ixz="-7.807E-05"
        iyy="0.010445"
        iyz="-3.427E-05"
        izz="0.056495" />
    </inertial>
    <visual>
      <origin
        xyz="0 0 0"
        rpy="0 0 0" />
      <geometry>
        <mesh
          filename="meshes/pelvis.STL" />
      </geometry>
      <material
        name="">
        <color
          rgba="0.89804 0.91765 0.92941 1" />
      </material>
    </visual>
    <collision>
      <origin
        xyz="0 0 0"
        rpy="0 0 0" />
      <geometry>
        <mesh
          filename="meshes/pelvis.STL" />
      </geometry>
    </collision>
  </link>
  <link
    name="waist_roll_link">
    <inertial>
      <origin
        xyz="0.13611 -0.0026969 0.010109"
        rpy="0 0 0" />
      <mass
        value="0.77779" />
      <inertia
        ixx="0.00060542"
        ixy="0"
        ixz="4.1E-07"
        iyy="0.0005688"
        iyz="0"
        izz="0.00062194" />
    </inertial>
    <visual>
      <origin
        xyz="0 0 0"
        rpy="0 0 0" />
      <geometry>
        <mesh
          filename="meshes/waist_roll_link.STL" />
      </geometry>
      <material
        name="">
        <color
          rgba="0.89804 0.91765 0.92941 1" />
      </material>
    </visual>
    <collision>
      <origin
        xyz="0 0 0"
        rpy="0 0 0" />
      <geometry>
        <mesh
          filename="meshes/waist_roll_link.STL" />
      </geometry>
    </collision>
  </link>
  <joint
    name="waist_roll_joint"
    type="revolute">
    <origin
      xyz="0 0 0"
      rpy="0 0 0" />
    <parent
      link="pelvis" />
    <child
      link="waist_roll_link" />
    <axis
      xyz="1 0 0" />
    <limit
      lower="-0.5236"
      upper="0.5236"
      effort="400"
      velocity="40" />
  </joint>
  <link
    name="waist_yaw_link">
    <inertial>
      <origin
        xyz="-7.5182E-08 -5.6001E-08 0.022793"
        rpy="0 0 0" />
      <mass
        value="0.67921" />
      <inertia
        ixx="0.0010239"
        ixy="0"
        ixz="0"
        iyy="0.0010484"
        iyz="0"
        izz="0.00036408" />
    </inertial>
    <visual>
      <origin
        xyz="0 0 0"
        rpy="0 0 0" />
      <geometry>
        <mesh
          filename="meshes/waist_yaw_link.STL" />
      </geometry>
      <material
        name="">
        <color
          rgba="0.89804 0.91765 0.92941 1" />
      </material>
    </visual>
    <collision>
      <origin
        xyz="0 0 0"
        rpy="0 0 0" />
      <geometry>
        <mesh
          filename="meshes/waist_yaw_link.STL" />
      </geometry>
    </collision>
  </link>
  <joint
    name="waist_yaw_joint"
    type="revolute">
    <origin
      xyz="0.136 -0.0026969600708463 0.00500000000000006"
      rpy="0 0 0" />
    <parent
      link="waist_roll_link" />
    <child
      link="waist_yaw_link" />
    <axis
      xyz="0 0 1" />
    <limit
      lower="-0.5236"
      upper="0.5236"
      effort="400"
      velocity="40" />
  </joint>
  <link
    name="waist_pitch_link">
    <inertial>
      <origin
        xyz="0.0051469 -1.2872E-08 0.19417"
        rpy="0 0 0" />
      <mass
        value="19.42" />
      <inertia
        ixx="0.47591"
        ixy="0"
        ixz="0.016864"
        iyy="0.458"
        iyz="0"
        izz="0.19868" />
    </inertial>
    <visual>
      <origin
        xyz="0 0 0"
        rpy="0 0 0" />
      <geometry>
        <mesh
          filename="meshes/waist_pitch_link.STL" />
      </geometry>
      <material
        name="">
        <color
          rgba="0.89804 0.91765 0.92941 1" />
      </material>
    </visual>
    <collision>
      <origin
        xyz="0 0 0"
        rpy="0 0 0" />
      <geometry>
        <mesh
          filename="meshes/waist_pitch_link.STL" />
      </geometry>
    </collision>
  </link>
  <joint
    name="waist_pitch_joint"
    type="revolute">
    <origin
      xyz="0 0 0.100000000000001"
      rpy="0 0 0" />
    <parent
      link="waist_yaw_link" />
    <child
      link="waist_pitch_link" />
    <axis
      xyz="0 1 0" />
    <limit
      lower="-0.5236"
      upper="1.0472"
      effort="400"
      velocity="40" />
  </joint>
  <link
    name="left_shoulder_pitch_link">
    <inertial>
      <origin
        xyz="-0.00044872 0.052703 2.4298E-07"
        rpy="0 0 0" />
      <mass
        value="0.80756" />
      <inertia
        ixx="0.00064093"
        ixy="8.3E-07"
        ixz="-3E-08"
        iyy="0.00067613"
        iyz="0"
        izz="0.00071049" />
    </inertial>
    <visual>
      <origin
        xyz="0 0 0"
        rpy="0 0 0" />
      <geometry>
        <mesh
          filename="meshes/left_shoulder_pitch_link.STL" />
      </geometry>
      <material
        name="">
        <color
          rgba="0.89804 0.91765 0.92941 1" />
      </material>
    </visual>
    <collision>
      <origin
        xyz="0 0 0"
        rpy="0 0 0" />
      <geometry>
        <mesh
          filename="meshes/left_shoulder_pitch_link.STL" />
      </geometry>
    </collision>
  </link>
  <joint
    name="left_shoulder_pitch_joint"
    type="revolute">
    <origin
      xyz="-0.0199999999999968 0.176399999999996 0.330200000000003"
      rpy="0 0 0" />
    <parent
      link="waist_pitch_link" />
    <child
      link="left_shoulder_pitch_link" />
    <axis
       xyz="0 1 0" />
    <limit
      lower="-3.1416"
      upper="0.7854"
      effort="400"
      velocity="40" />
  </joint>
  <link
    name="left_shoulder_roll_link">
    <inertial>
      <origin
        xyz="-0.029786 -1.5469E-05 -0.082382"
        rpy="0 0 0" />
      <mass
        value="1.0192" />
      <inertia
        ixx="0.00129704"
        ixy="1.24E-06"
        ixz="-0.00017008"
        iyy="0.00136052"
        iyz="1.69E-06"
        izz="0.0009243" />
    </inertial>
    <visual>
      <origin
        xyz="0 0 0"
        rpy="0 0 0" />
      <geometry>
        <mesh
          filename="meshes/left_shoulder_roll_link.STL" />
      </geometry>
      <material
        name="">
        <color
          rgba="0.89804 0.91765 0.92941 1" />
      </material>
    </visual>
    <collision>
      <origin
        xyz="0 0 0"
        rpy="0 0 0" />
      <geometry>
        <mesh
          filename="meshes/left_shoulder_roll_link.STL" />
      </geometry>
    </collision>
  </link>
  <joint
    name="left_shoulder_roll_joint"
    type="revolute">
    <origin
      xyz="0.037000000000001 0.055000000000004 0"
      rpy="0 0 0" />
    <parent
      link="left_shoulder_pitch_link" />
    <child
      link="left_shoulder_roll_link" />
    <axis
       xyz="1 0 0" />
    <limit
      lower="-0.6981"
      upper="3.1416"
      effort="400"
      velocity="40" />
  </joint>
  <link
    name="left_shoulder_yaw_link">
    <inertial>
      <origin
        xyz="1.2055E-08 0.00039438 -0.10267"
        rpy="0 0 0" />
      <mass
        value="0.91899" />
      <inertia
        ixx="0.0014881"
        ixy="2E-08"
        ixz="0"
        iyy="0.00141856"
        iyz="4.47E-06"
        izz="0.00082487" />
    </inertial>
    <visual>
      <origin
        xyz="0 0 0"
        rpy="0 0 0" />
      <geometry>
        <mesh
          filename="meshes/left_shoulder_yaw_link.STL" />
      </geometry>
      <material
        name="">
        <color
          rgba="0.89804 0.91765 0.92941 1" />
      </material>
    </visual>
    <collision>
      <origin
        xyz="0 0 0"
        rpy="0 0 0" />
      <geometry>
        <mesh
          filename="meshes/left_shoulder_yaw_link.STL" />
      </geometry>
    </collision>
  </link>
  <joint
    name="left_shoulder_yaw_joint"
    type="revolute">
    <origin
      xyz="-0.0349999999999999 0 -0.125"
      rpy="0 0 0" />
    <parent
      link="left_shoulder_roll_link" />
    <child
      link="left_shoulder_yaw_link" />
    <axis
      xyz="0 0 1" />
    <limit
      lower="-1.5708"
      upper="1.5708"
      effort="400"
      velocity="40" />
  </joint>
  <link
    name="left_elbow_link">
    <inertial>
      <origin
        xyz="5.3776E-16 0.027765 -0.081713"
        rpy="0 0 0" />
      <mass
        value="1.1024" />
      <inertia
        ixx="0.0015351"
        ixy="0"
        ixz="0"
        iyy="0.0014811"
        iyz="0.00019307"
        izz="0.0010473" />
    </inertial>
    <visual>
      <origin
        xyz="0 0 0"
        rpy="0 0 0" />
      <geometry>
        <mesh
          filename="meshes/left_elbow_link.STL" />
      </geometry>
      <material
        name="">
        <color
          rgba="0.89804 0.91765 0.92941 1" />
      </material>
    </visual>
    <collision>
      <origin
        xyz="0 0 0"
        rpy="0 0 0" />
      <geometry>
        <mesh
          filename="meshes/left_elbow_link.STL" />
      </geometry>
    </collision>
  </link>
  <joint
    name="left_elbow_joint"
    type="revolute">
    <origin
      xyz="0 -0.037 -0.114999999999999"
      rpy="0 0 0" />
    <parent
      link="left_shoulder_yaw_link" />
    <child
      link="left_elbow_link" />
    <axis
      xyz="0 1 0" />
    <limit
      lower="-2.4435"
      upper="0.1745"
      effort="400"
      velocity="40" />
  </joint>
  <link
    name="left_wrist_yaw_link">
    <inertial>
      <origin
        xyz="0.053864 0.00012644 0.0015228"
        rpy="0 0 0" />
      <mass
        value="0.67025" />
      <inertia
        ixx="0.00044228"
        ixy="5.9E-07"
        ixz="-2.25E-06"
        iyy="0.00099243"
        iyz="1.94E-06"
        izz="0.00101021" />
    </inertial>
    <visual>
      <origin
        xyz="0 0 0"
        rpy="0 0 0" />
      <geometry>
        <mesh
          filename="meshes/left_wrist_yaw_link.STL" />
      </geometry>
      <material
        name="">
        <color
          rgba="0.89804 0.91765 0.92941 1" />
      </material>
    </visual>
    <collision>
      <origin
        xyz="0 0 0"
        rpy="0 0 0" />
      <geometry>
        <mesh
          filename="meshes/left_wrist_yaw_link.STL" />
      </geometry>
    </collision>
  </link>
  <joint
    name="left_wrist_yaw_joint"
    type="revolute">
    <origin
      xyz="0 0.035 -0.125"
      rpy="0 1.5707963267949 0" />
    <parent
      link="left_elbow_link" />
    <child
      link="left_wrist_yaw_link" />
    <axis
       xyz="1 0 0" />
    <limit
      lower="-1.5708"
      upper="1.5708"
      effort="400"
      velocity="40" />
  </joint>
  <link
    name="left_wrist_pitch_link">
    <inertial>
      <origin
        xyz="0.0022975 -6.2346E-09 3.4863E-09"
        rpy="0 0 0" />
      <mass
        value="0.0012195" />
      <inertia
        ixx="2E-08"
        ixy="0"
        ixz="0"
        iyy="2E-08"
        iyz="0"
        izz="3E-08" />
    </inertial>
    <visual>
      <origin
        xyz="0 0 0"
        rpy="0 0 0" />
      <geometry>
        <mesh
          filename="meshes/left_wrist_pitch_link.STL" />
      </geometry>
      <material
        name="">
        <color
          rgba="0.89804 0.91765 0.92941 1" />
      </material>
    </visual>
    <collision>
      <origin
        xyz="0 0 0"
        rpy="0 0 0" />
      <geometry>
        <mesh
          filename="meshes/left_wrist_pitch_link.STL" />
      </geometry>
    </collision>
  </link>
  <joint
    name="left_wrist_pitch_joint"
    type="revolute">
    <origin
      xyz="0.14299999999986 0.00193610368711286 0.0173925703249677"
      rpy="-0.110905396506169 0.0280968692676611 -0.00312851172176722" />
    <parent
      link="left_wrist_yaw_link" />
    <child
      link="left_wrist_pitch_link" />
    <axis
       xyz="0 1 0" />
    <limit
      lower="-1.3963"
      upper="1.3963"
      effort="400"
      velocity="40" />
  </joint>
  <link
    name="left_wrist_roll_link">
    <inertial>
      <origin
        xyz="0.082689 0.0062323 0.0064285"
        rpy="0 0 0" />
      <mass
        value="0.45656" />
      <inertia
        ixx="0.00042604"
        ixy="7.8733E-05"
        ixz="9.2764E-05"
        iyy="0.000956"
        iyz="9.1752E-06"
        izz="0.0012402" />
    </inertial>
    <visual>
      <origin
        xyz="0 0 0"
        rpy="0 0 0" />
      <geometry>
        <mesh
          filename="meshes/left_wrist_roll_link.STL" />
      </geometry>
      <material
        name="">
        <color
          rgba="0.89804 0.91765 0.92941 1" />
      </material>
    </visual>
    <collision>
      <origin
        xyz="0 0 0"
        rpy="0 0 0" />
      <geometry>
        <mesh
          filename="meshes/left_wrist_roll_link.STL" />
      </geometry>
    </collision>
  </link>
  <joint
    name="left_wrist_roll_joint"
    type="revolute">
    <origin
      xyz="0.00850000000001899 0 0"
      rpy="0 0 0" />
    <parent
      link="left_wrist_pitch_link" />
    <child
      link="left_wrist_roll_link" />
    <axis
      xyz="0 0 1" />
    <limit
      lower="-0.5236"
      upper="0.6981"
      effort="400"
      velocity="40" />
  </joint>
  <link
    name="right_shoulder_pitch_link">
    <inertial>
      <origin
        xyz="0.00044872 -0.052703 2.4354E-07"
        rpy="0 0 0" />
      <mass
        value="0.80756" />
      <inertia
        ixx="0.00064093"
        ixy="8.3E-07"
        ixz="3E-08"
        iyy="0.00067613"
        iyz="0"
        izz="0.00071049" />
    </inertial>
    <visual>
      <origin
        xyz="0 0 0"
        rpy="0 0 0" />
      <geometry>
        <mesh
          filename="meshes/right_shoulder_pitch_link.STL" />
      </geometry>
      <material
        name="">
        <color
          rgba="0.89804 0.91765 0.92941 1" />
      </material>
    </visual>
    <collision>
      <origin
        xyz="0 0 0"
        rpy="0 0 0" />
      <geometry>
        <mesh
          filename="meshes/right_shoulder_pitch_link.STL" />
      </geometry>
    </collision>
  </link>
  <joint
    name="right_shoulder_pitch_joint"
    type="revolute">
    <origin
      xyz="-0.0199999999999955 -0.176399999999996 0.330200000000003"
      rpy="0 0 0" />
    <parent
      link="waist_pitch_link" />
    <child
      link="right_shoulder_pitch_link" />
    <axis
      xyz="0 1 0" />
    <limit
      lower="-3.1416"
      upper="0.7854"
      effort="400"
      velocity="40" />
  </joint>
  <link
    name="right_shoulder_roll_link">
    <inertial>
      <origin
        xyz="0.029786 1.5469E-05 -0.082382"
        rpy="0 0 0" />
      <mass
        value="1.0192" />
      <inertia
        ixx="0.00129704"
        ixy="1.24E-06"
        ixz="0.00017008"
        iyy="0.00136052"
        iyz="-1.69E-06"
        izz="0.0009243" />
    </inertial>
    <visual>
      <origin
        xyz="0 0 0"
        rpy="0 0 0" />
      <geometry>
        <mesh
          filename="meshes/right_shoulder_roll_link.STL" />
      </geometry>
      <material
        name="">
        <color
          rgba="0.89804 0.91765 0.92941 1" />
      </material>
    </visual>
    <collision>
      <origin
        xyz="0 0 0"
        rpy="0 0 0" />
      <geometry>
        <mesh
          filename="meshes/right_shoulder_roll_link.STL" />
      </geometry>
    </collision>
  </link>
  <joint
    name="right_shoulder_roll_joint"
    type="revolute">
    <origin
      xyz="-0.0370000000000002 -0.055000000000004 0"
      rpy="0 0 0" />
    <parent
      link="right_shoulder_pitch_link" />
    <child
      link="right_shoulder_roll_link" />
    <axis
      xyz="1 0 0" />
    <limit
      lower="-3.1416"
      upper="0.6981"
      effort="400"
      velocity="40" />
  </joint>
  <link
    name="right_shoulder_yaw_link">
    <inertial>
      <origin
        xyz="-3.3047E-08 -0.00039438 -0.10267"
        rpy="0 0 0" />
      <mass
        value="0.91899" />
      <inertia
        ixx="0.0014881"
        ixy="2E-08"
        ixz="0"
        iyy="0.00141856"
        iyz="-4.47E-06"
        izz="0.00082487" />
    </inertial>
    <visual>
      <origin
        xyz="0 0 0"
        rpy="0 0 0" />
      <geometry>
        <mesh
          filename="meshes/right_shoulder_yaw_link.STL" />
      </geometry>
      <material
        name="">
        <color
          rgba="0.89804 0.91765 0.92941 1" />
      </material>
    </visual>
    <collision>
      <origin
        xyz="0 0 0"
        rpy="0 0 0" />
      <geometry>
        <mesh
          filename="meshes/right_shoulder_yaw_link.STL" />
      </geometry>
    </collision>
  </link>
  <joint
    name="right_shoulder_yaw_joint"
    type="revolute">
    <origin
      xyz="0.035 0 -0.125"
      rpy="0 0 0" />
    <parent
      link="right_shoulder_roll_link" />
    <child
      link="right_shoulder_yaw_link" />
    <axis
      xyz="0 0 1" />
    <limit
      lower="-1.5708"
      upper="1.5708"
      effort="400"
      velocity="40" />
  </joint>
  <link
    name="right_elbow_link">
    <inertial>
      <origin
        xyz="-9.7838E-16 -0.027765 -0.081713"
        rpy="0 0 0" />
      <mass
        value="1.1024" />
      <inertia
        ixx="0.00153506"
        ixy="0"
        ixz="0"
        iyy="0.00148114"
        iyz="-0.00019307"
        izz="0.00104733" />
    </inertial>
    <visual>
      <origin
        xyz="0 0 0"
        rpy="0 0 0" />
      <geometry>
        <mesh
          filename="meshes/right_elbow_link.STL" />
      </geometry>
      <material
        name="">
        <color
          rgba="0.89804 0.91765 0.92941 1" />
      </material>
    </visual>
    <collision>
      <origin
        xyz="0 0 0"
        rpy="0 0 0" />
      <geometry>
        <mesh
          filename="meshes/right_elbow_link.STL" />
      </geometry>
    </collision>
  </link>
  <joint
    name="right_elbow_joint"
    type="revolute">
    <origin
      xyz="0 0.0370000000000002 -0.114999999999999"
      rpy="0 0 0" />
    <parent
      link="right_shoulder_yaw_link" />
    <child
      link="right_elbow_link" />
    <axis
       xyz="0 1 0" />
    <limit
      lower="-2.4435"
      upper="0.1745"
      effort="400"
      velocity="40" />
  </joint>
  <link
    name="right_wrist_yaw_link">
    <inertial>
      <origin
        xyz="0.053864 -0.00012644 -0.0015228"
        rpy="0 0 0" />
      <mass
        value="0.67025" />
      <inertia
        ixx="0.00044228"
        ixy="-5.9E-07"
        ixz="2.25E-06"
        iyy="0.00099243"
        iyz="1.94E-06"
        izz="0.00101021" />
    </inertial>
    <visual>
      <origin
        xyz="0 0 0"
        rpy="0 0 0" />
      <geometry>
        <mesh
          filename="meshes/right_wrist_yaw_link.STL" />
      </geometry>
      <material
        name="">
        <color
          rgba="0.89804 0.91765 0.92941 1" />
      </material>
    </visual>
    <collision>
      <origin
        xyz="0 0 0"
        rpy="0 0 0" />
      <geometry>
        <mesh
          filename="meshes/right_wrist_yaw_link.STL" />
      </geometry>
    </collision>
  </link>
  <joint
    name="right_wrist_yaw_joint"
    type="revolute">
    <origin
      xyz="0 -0.035 -0.125"
      rpy="0 1.5707963267949 0" />
    <parent
      link="right_elbow_link" />
    <child
      link="right_wrist_yaw_link" />
    <axis
       xyz="1 0 0" />
    <limit
      lower="-1.5708"
      upper="1.5708"
      effort="400"
      velocity="40" />
  </joint>
  <link
    name="right_wrist_pitch_link">
    <inertial>
      <origin
        xyz="0.0022975 6.2346E-09 -3.4863E-09"
        rpy="0 0 0" />
      <mass
        value="0.0012195" />
      <inertia
        ixx="2E-08"
        ixy="0"
        ixz="0"
        iyy="2E-08"
        iyz="0"
        izz="3E-08" />
    </inertial>
    <visual>
      <origin
        xyz="0 0 0"
        rpy="0 0 0" />
      <geometry>
        <mesh
          filename="meshes/right_wrist_pitch_link.STL" />
      </geometry>
      <material
        name="">
        <color
          rgba="0.89804 0.91765 0.92941 1" />
      </material>
    </visual>
    <collision>
      <origin
        xyz="0 0 0"
        rpy="0 0 0" />
      <geometry>
        <mesh
          filename="meshes/right_wrist_pitch_link.STL" />
      </geometry>
    </collision>
  </link>
  <joint
    name="right_wrist_pitch_joint"
    type="revolute">
    <origin
      xyz="0.14299999999986 -0.00193610368712027 -0.0173925703249581"
      rpy="-0.110905396506169 -0.0280968692676612 0.00312851172176724" />
    <parent
      link="right_wrist_yaw_link" />
    <child
      link="right_wrist_pitch_link" />
    <axis
      xyz="0 1 0" />
    <limit
      lower="-1.3963"
      upper="1.3963"
      effort="400"
      velocity="40" />
  </joint>
  <link
    name="right_wrist_roll_link">
    <inertial>
      <origin
        xyz="0.082502 -0.0062021 0.0077858"
        rpy="0 0 0" />
      <mass
        value="0.45656" />
      <inertia
        ixx="0.00043193"
        ixy="-7.793E-05"
        ixz="0.00011592"
        iyy="0.0009561"
        iyz="-1.2819E-05"
        izz="0.0012342" />
    </inertial>
    <visual>
      <origin
        xyz="0 0 0"
        rpy="0 0 0" />
      <geometry>
        <mesh
          filename="meshes/right_wrist_roll_link.STL" />
      </geometry>
      <material
        name="">
        <color
          rgba="0.89804 0.91765 0.92941 1" />
      </material>
    </visual>
    <collision>
      <origin
        xyz="0 0 0"
        rpy="0 0 0" />
      <geometry>
        <mesh
          filename="meshes/right_wrist_roll_link.STL" />
      </geometry>
    </collision>
  </link>
  <joint
    name="right_wrist_roll_joint"
    type="revolute">
    <origin
      xyz="0.00850000000000445 0 0"
      rpy="0 0.0282704628994441 0" />
    <parent
      link="right_wrist_pitch_link" />
    <child
      link="right_wrist_roll_link" />
    <axis
      xyz="-0.0282666973344013 0 0.999600417077647" />
    <limit
      lower="-0.6981"
      upper="0.5236"
      effort="400"
      velocity="40" />
  </joint>
  <link
    name="left_hip_roll_link">
    <inertial>
      <origin
        xyz="0.047601 1.4826E-08 -0.0016085"
        rpy="0 0 0" />
      <mass
        value="0.82351" />
      <inertia
        ixx="0.00066543"
        ixy="0"
        ixz="3.18E-06"
        iyy="0.00068288"
        iyz="0"
        izz="0.00074433" />
    </inertial>
    <visual>
      <origin
        xyz="0 0 0"
        rpy="0 0 0" />
      <geometry>
        <mesh
          filename="meshes/left_hip_roll_link.STL" />
      </geometry>
      <material
        name="">
        <color
          rgba="0.89804 0.91765 0.92941 1" />
      </material>
    </visual>
    <collision>
      <origin
        xyz="0 0 0"
        rpy="0 0 0" />
      <geometry>
        <mesh
          filename="meshes/left_hip_roll_link.STL" />
      </geometry>
    </collision>
  </link>
  <joint
    name="left_hip_roll_joint"
    type="revolute">
    <origin
      xyz="0.0960000000000001 0.102303039929154 -0.035"
      rpy="0 0 0" />
    <parent
      link="pelvis" />
    <child
      link="left_hip_roll_link" />
    <axis
       xyz="1 0 0" />
    <limit
      lower="-0.7854"
      upper="0.5236"
      effort="400"
      velocity="40" />
  </joint>
  <link
    name="left_hip_yaw_link">
    <inertial>
      <origin
        xyz="5.8269E-09 3.9215E-09 -0.02534"
        rpy="0 0 0" />
      <mass
        value="0.39644" />
      <inertia
        ixx="0.00018725"
        ixy="-6.3202E-11"
        ixz="-7.5907E-11"
        iyy="0.00020217"
        iyz="-2.8319E-11"
        izz="0.00019795" />
    </inertial>
    <visual>
      <origin
        xyz="0 0 0"
        rpy="0 0 0" />
      <geometry>
        <mesh
          filename="meshes/left_hip_yaw_link.STL" />
      </geometry>
      <material
        name="">
        <color
          rgba="0.89804 0.91765 0.92941 1" />
      </material>
    </visual>
    <collision>
      <origin
        xyz="0 0 0"
        rpy="0 0 0" />
      <geometry>
        <mesh
          filename="meshes/left_hip_yaw_link.STL" />
      </geometry>
    </collision>
  </link>
  <joint
    name="left_hip_yaw_joint"
    type="revolute">
    <origin
      xyz="0.0499999999999999 0 -0.0349999999999999"
      rpy="0 0 0" />
    <parent
      link="left_hip_roll_link" />
    <child
      link="left_hip_yaw_link" />
    <axis
      xyz="0 0 1" />
    <limit
      lower="-0.8727"
      upper="0.8727"
      effort="400"
      velocity="40" />
  </joint>
  <link
    name="left_hip_pitch_link">
    <inertial>
      <origin
        xyz="-0.026282 -2.0455E-05 -0.17181"
        rpy="0 0 0" />
      <mass
        value="6.4776" />
      <inertia
        ixx="0.055549"
        ixy="5.2E-07"
        ixz="0.00217698"
        iyy="0.055297"
        iyz="3.18E-06"
        izz="0.019325" />
    </inertial>
    <visual>
      <origin
        xyz="0 0 0"
        rpy="0 0 0" />
      <geometry>
        <mesh
          filename="meshes/left_hip_pitch_link.STL" />
      </geometry>
      <material
        name="">
        <color
          rgba="0.89804 0.91765 0.92941 1" />
      </material>
    </visual>
    <collision>
      <origin
        xyz="0 0 0"
        rpy="0 0 0" />
      <geometry>
        <mesh
          filename="meshes/left_hip_pitch_link.STL" />
      </geometry>
    </collision>
  </link>
  <joint
    name="left_hip_pitch_joint"
    type="revolute">
    <origin
      xyz="0 -0.00100000000000053 -0.0440000000000002"
      rpy="0 0 0" />
    <parent
      link="left_hip_yaw_link" />
    <child
      link="left_hip_pitch_link" />
    <axis
      xyz="0 1 0" />
    <limit
      lower="-2.5307"
      upper="0.6981"
      effort="400"
      velocity="40" />
  </joint>
  <link
    name="left_knee_link">
    <inertial>
      <origin
        xyz="0.019387 0.0016128 -0.15668"
        rpy="0 0 0" />
      <mass
        value="1.3874" />
      <inertia
        ixx="0.01289811"
        ixy="-5.041E-05"
        ixz="0.00029155"
        iyy="0.01220914"
        iyz="-0.00011192"
        izz="0.00186474" />
    </inertial>
    <visual>
      <origin
        xyz="0 0 0"
        rpy="0 0 0" />
      <geometry>
        <mesh
          filename="meshes/left_knee_link.STL" />
      </geometry>
      <material
        name="">
        <color
          rgba="0.89804 0.91765 0.92941 1" />
      </material>
    </visual>
    <collision>
      <origin
        xyz="0 0 0"
        rpy="0 0 0" />
      <geometry>
        <mesh
          filename="meshes/left_knee_link.STL" />
      </geometry>
    </collision>
  </link>
  <joint
    name="left_knee_joint"
    type="revolute">
    <origin
      xyz="-0.03 0 -0.324"
      rpy="0 0 0" />
    <parent
      link="left_hip_pitch_link" />
    <child
      link="left_knee_link" />
    <axis
      xyz="0 1 0" />
    <limit
      lower="0"
      upper="2.5307"
      effort="400"
      velocity="40" />
  </joint>
  <link
    name="left_ankle_pitch_link">
    <inertial>
      <origin
        xyz="3.0174E-09 -6.2E-09 -0.0022975"
        rpy="0 0 0" />
      <mass
        value="0.0012195" />
      <inertia
        ixx="3E-08"
        ixy="0"
        ixz="0"
        iyy="2E-08"
        iyz="0"
        izz="2E-08" />
    </inertial>
    <visual>
      <origin
        xyz="0 0 0"
        rpy="0 0 0" />
      <geometry>
        <mesh
          filename="meshes/left_ankle_pitch_link.STL" />
      </geometry>
      <material
        name="">
        <color
          rgba="0.89804 0.91765 0.92941 1" />
      </material>
    </visual>
    <collision>
      <origin
        xyz="0 0 0"
        rpy="0 0 0" />
      <geometry>
        <mesh
          filename="meshes/left_ankle_pitch_link.STL" />
      </geometry>
    </collision>
  </link>
  <joint
    name="left_ankle_pitch_joint"
    type="revolute">
    <origin
      xyz="0.0375000000001061 0 -0.32600000000005"
      rpy="0 0.0262534221029132 0" />
    <parent
      link="left_knee_link" />
    <child
      link="left_ankle_pitch_link" />
    <axis
       xyz="0 1 0" />
    <limit
      lower="-0.5236"
      upper="0.7854"
      effort="400"
      velocity="40" />
  </joint>
  <link
    name="left_ankle_roll_link">
    <inertial>
      <origin
        xyz="0.038053 -1.2906E-15 -0.04952"
        rpy="0 0 0" />
      <mass
        value="0.55286" />
      <inertia
        ixx="0.00092504"
        ixy="1.8252E-17"
        ixz="-4.7704E-06"
        iyy="0.0028003"
        iyz="7.9589E-18"
        izz="0.0030825" />
    </inertial>
    <visual>
      <origin
        xyz="0 0 0"
        rpy="0 0 0" />
      <geometry>
        <mesh
          filename="meshes/left_ankle_roll_link.STL" />
      </geometry>
      <material
        name="">
        <color
          rgba="0.89804 0.91765 0.92941 1" />
      </material>
    </visual>
    <collision>
      <origin
        xyz="0 0 0"
        rpy="0 0 0" />
      <geometry>
        <mesh
          filename="meshes/left_ankle_roll_link.STL" />
      </geometry>
    </collision>
  </link>
  <joint
    name="left_ankle_roll_joint"
    type="revolute">
    <origin
      xyz="0 0 -0.00849999999998929"
      rpy="-0.000708665321665216 0 0" />
    <parent
      link="left_ankle_pitch_link" />
    <child
      link="left_ankle_roll_link" />
    <axis
       xyz="1 0 0" />
    <limit
      lower="-0.6109"
      upper="0.5236"
      effort="400"
      velocity="40" />
  </joint>
  <link
    name="right_hip_roll_link">
    <inertial>
      <origin
        xyz="0.047601 1.4826E-08 -0.0016085"
        rpy="0 0 0" />
      <mass
        value="0.82351" />
      <inertia
        ixx="0.00066543"
        ixy="0"
        ixz="3.18E-06"
        iyy="0.00068288"
        iyz="0"
        izz="0.00074433" />
    </inertial>
    <visual>
      <origin
        xyz="0 0 0"
        rpy="0 0 0" />
      <geometry>
        <mesh
          filename="meshes/right_hip_roll_link.STL" />
      </geometry>
      <material
        name="">
        <color
          rgba="0.89804 0.91765 0.92941 1" />
      </material>
    </visual>
    <collision>
      <origin
        xyz="0 0 0"
        rpy="0 0 0" />
      <geometry>
        <mesh
          filename="meshes/right_hip_roll_link.STL" />
      </geometry>
    </collision>
  </link>
  <joint
    name="right_hip_roll_joint"
    type="revolute">
    <origin
      xyz="0.0960000000000001 -0.107696960070846 -0.035"
      rpy="0 0 0" />
    <parent
      link="pelvis" />
    <child
      link="right_hip_roll_link" />
    <axis
       xyz="1 0 0" />
    <limit
      lower="-0.5236"
      upper="0.7854"
      effort="400"
      velocity="40" />
  </joint>
  <link
    name="right_hip_yaw_link">
    <inertial>
      <origin
        xyz="5.8269E-09 3.9215E-09 -0.02534"
        rpy="0 0 0" />
      <mass
        value="0.39644" />
      <inertia
        ixx="0.00018725"
        ixy="-6.3202E-11"
        ixz="-7.5907E-11"
        iyy="0.00020217"
        iyz="-2.8319E-11"
        izz="0.00019795" />
    </inertial>
    <visual>
      <origin
        xyz="0 0 0"
        rpy="0 0 0" />
      <geometry>
        <mesh
          filename="meshes/right_hip_yaw_link.STL" />
      </geometry>
      <material
        name="">
        <color
          rgba="0.89804 0.91765 0.92941 1" />
      </material>
    </visual>
    <collision>
      <origin
        xyz="0 0 0"
        rpy="0 0 0" />
      <geometry>
        <mesh
          filename="meshes/right_hip_yaw_link.STL" />
      </geometry>
    </collision>
  </link>
  <joint
    name="right_hip_yaw_joint"
    type="revolute">
    <origin
      xyz="0.0499999999999999 0 -0.0349999999999999"
      rpy="0 0 0" />
    <parent
      link="right_hip_roll_link" />
    <child
      link="right_hip_yaw_link" />
    <axis
      xyz="0 0 1" />
    <limit
      lower="-0.8727"
      upper="0.8727"
      effort="400"
      velocity="40" />
  </joint>
  <link
    name="right_hip_pitch_link">
    <inertial>
      <origin
        xyz="-0.026282 -2.0455E-05 -0.17181"
        rpy="0 0 0" />
      <mass
        value="6.4776" />
      <inertia
        ixx="0.055549"
        ixy="5.2E-07"
        ixz="0.00217698"
        iyy="0.055297"
        iyz="3.18E-06"
        izz="0.019325" />
    </inertial>
    <visual>
      <origin
        xyz="0 0 0"
        rpy="0 0 0" />
      <geometry>
        <mesh
          filename="meshes/right_hip_pitch_link.STL" />
      </geometry>
      <material
        name="">
        <color
          rgba="0.89804 0.91765 0.92941 1" />
      </material>
    </visual>
    <collision>
      <origin
        xyz="0 0 0"
        rpy="0 0 0" />
      <geometry>
        <mesh
          filename="meshes/right_hip_pitch_link.STL" />
      </geometry>
    </collision>
  </link>
  <joint
    name="right_hip_pitch_joint"
    type="revolute">
    <origin
      xyz="0 0.00100000000000006 -0.0439999999999999"
      rpy="0 0 0" />
    <parent
      link="right_hip_yaw_link" />
    <child
      link="right_hip_pitch_link" />
    <axis
      xyz="0 1 0" />
    <limit
      lower="-2.5307"
      upper="0.6981"
      effort="400"
      velocity="40" />
  </joint>
  <link
    name="right_knee_link">
    <inertial>
      <origin
        xyz="0.019387 0.0016128 -0.15668"
        rpy="0 0 0" />
      <mass
        value="1.3874" />
      <inertia
        ixx="0.01289811"
        ixy="-5.041E-05"
        ixz="0.00029155"
        iyy="0.01220914"
        iyz="-0.00011192"
        izz="0.00186474" />
    </inertial>
    <visual>
      <origin
        xyz="0 0 0"
        rpy="0 0 0" />
      <geometry>
        <mesh
          filename="meshes/right_knee_link.STL" />
      </geometry>
      <material
        name="">
        <color
          rgba="0.89804 0.91765 0.92941 1" />
      </material>
    </visual>
    <collision>
      <origin
        xyz="0 0 0"
        rpy="0 0 0" />
      <geometry>
        <mesh
          filename="meshes/right_knee_link.STL" />
      </geometry>
    </collision>
  </link>
  <joint
    name="right_knee_joint"
    type="revolute">
    <origin
      xyz="-0.03 0 -0.324"
      rpy="0 0 0" />
    <parent
      link="right_hip_pitch_link" />
    <child
      link="right_knee_link" />
    <axis
      xyz="0 1 0" />
    <limit
      lower="0"
      upper="2.4407"
      effort="400"
      velocity="40" />
  </joint>
  <link
    name="right_ankle_pitch_link">
    <inertial>
      <origin
        xyz="3.0174E-09 -6.2001E-09 -0.0022975"
        rpy="0 0 0" />
      <mass
        value="0.0012195" />
      <inertia
        ixx="3E-08"
        ixy="0"
        ixz="0"
        iyy="2E-08"
        iyz="0"
        izz="2E-08" />
    </inertial>
    <visual>
      <origin
        xyz="0 0 0"
        rpy="0 0 0" />
      <geometry>
        <mesh
          filename="meshes/right_ankle_pitch_link.STL" />
      </geometry>
      <material
        name="">
        <color
          rgba="0.89804 0.91765 0.92941 1" />
      </material>
    </visual>
    <collision>
      <origin
        xyz="0 0 0"
        rpy="0 0 0" />
      <geometry>
        <mesh
          filename="meshes/right_ankle_pitch_link.STL" />
      </geometry>
    </collision>
  </link>
  <joint
    name="right_ankle_pitch_joint"
    type="revolute">
    <origin
      xyz="0.0375000000001132 0 -0.32600000000005"
      rpy="0 0.0262534221029132 0" />
    <parent
      link="right_knee_link" />
    <child
      link="right_ankle_pitch_link" />
    <axis
       xyz="0 1 0" />
    <limit
      lower="-0.5236"
      upper="0.7854"
      effort="400"
      velocity="40" />
  </joint>
  <link
    name="right_ankle_roll_link">
    <inertial>
      <origin
        xyz="0.038053 4.6352E-15 -0.04952"
        rpy="0 0 0" />
      <mass
        value="0.55286" />
      <inertia
        ixx="0.00092504"
        ixy="1.8613E-17"
        ixz="4.77E-06"
        iyy="0.0028003"
        iyz="8.1065E-18"
        izz="0.0030825" />
    </inertial>
    <visual>
      <origin
        xyz="0 0 0"
        rpy="0 0 0" />
      <geometry>
        <mesh
          filename="meshes/right_ankle_roll_link.STL" />
      </geometry>
      <material
        name="">
        <color
          rgba="0.89804 0.91765 0.92941 1" />
      </material>
    </visual>
    <collision>
      <origin
        xyz="0 0 0"
        rpy="0 0 0" />
      <geometry>
        <mesh
          filename="meshes/right_ankle_roll_link.STL" />
      </geometry>
    </collision>
  </link>
  <joint
    name="right_ankle_roll_joint"
    type="revolute">
    <origin
      xyz="0 0 -0.00849999999998974"
      rpy="-0.000708665321665188 0 0" />
    <parent
      link="right_ankle_pitch_link" />
    <child
      link="right_ankle_roll_link" />
    <axis
       xyz="1 0 0" />
    <limit
      lower="-0.5236"
      upper="0.6109"
      effort="400"
      velocity="40" />
  </joint>
</robot>